<?xml version="1.0" encoding="utf-8"?>
<!-- This URDF was automatically created by SolidWorks to URDF Exporter! Originally created by Stephen Brawner (brawner@gmail.com) 
     Commit Version: 1.6.0-4-g7f85cfe  Build Version: 1.6.7995.38578
     For more information, please see http://wiki.ros.org/sw_urdf_exporter -->
<robot
  name="sa2000h_urdf_0416">
  <link
    name="base_link">
    <!-- <inertial>
      <origin
        xyz="-0.026247 -0.00053463 0.10551"
        rpy="0 0 0" />
      <mass
        value="0.21182" />
      <inertia
        ixx="0.0026006"
        ixy="-1.5443E-05"
        ixz="-0.00014709"
        iyy="0.0035319"
        iyz="-2.1489E-06"
        izz="0.0038574" />
    </inertial> -->
    <visual>
      <origin
        xyz="0 0 0"
        rpy="0 0 0" />
      <geometry>
        <mesh
          filename="https://raw.githubusercontent.com/shine-tong/urdf/main/sa2000h_urdf_0416/meshes/base_link.STL" />
      </geometry>
      <material
        name="">
        <color
          rgba="1 1 0.50196 1" />
      </material>
    </visual>
    <collision>
      <origin
        xyz="0 0 0"
        rpy="0 0 0" />
      <geometry>
        <mesh
          filename="https://raw.githubusercontent.com/shine-tong/urdf/main/sa2000h_urdf_0416/meshes/base_link.STL" />
      </geometry>
    </collision>
  </link>
  <link
    name="link1">
    <inertial>
      <origin
        xyz="0.073279 0.0022201 -0.047493"
        rpy="0 0 0" />
      <mass
        value="0.1259" />
      <inertia
        ixx="0.0013004"
        ixy="-3.1118E-05"
        ixz="-0.00050189"
        iyy="0.0025316"
        iyz="-1.0879E-05"
        izz="0.0023997" />
    </inertial>
    <visual>
      <origin
        xyz="0 0 0"
        rpy="0 0 0" />
      <geometry>
        <mesh
          filename="https://raw.githubusercontent.com/shine-tong/urdf/main/sa2000h_urdf_0416/meshes/link1.STL" />
      </geometry>
      <material
        name="">
        <color
          rgba="0.79216 0.81961 0.93333 1" />
      </material>
    </visual>
    <collision>
      <origin
        xyz="0 0 0"
        rpy="0 0 0" />
      <geometry>
        <mesh
          filename="https://raw.githubusercontent.com/shine-tong/urdf/main/sa2000h_urdf_0416/meshes/link1.STL" />
      </geometry>
    </collision>
  </link>
  <joint
    name="joint1"
    type="revolute">
    <origin
      xyz="0.0055 0 0.417"
      rpy="0 0 0" />
    <parent
      link="base_link" />
    <child
      link="link1" />
    <axis
      xyz="0 0 -1" />
    <limit
      lower="-2.8798"
      upper="2.8798"
      effort="0"
      velocity="0" />
  </joint>
  <link
    name="link2">
    <inertial>
      <origin
        xyz="0.35659 0.019477 0.1707"
        rpy="0 0 0" />
      <mass
        value="0.062211" />
      <inertia
        ixx="0.00031907"
        ixy="-2.8093E-05"
        ixz="-1.0933E-05"
        iyy="0.0050925"
        iyz="-2.6636E-05"
        izz="0.0051605" />
    </inertial>
    <visual>
      <origin
        xyz="0 0 0"
        rpy="0 0 0" />
      <geometry>
        <mesh
          filename="https://raw.githubusercontent.com/shine-tong/urdf/main/sa2000h_urdf_0416/meshes/link2.STL" />
      </geometry>
      <material
        name="">
        <color
          rgba="1 1 0.50196 1" />
      </material>
    </visual>
    <collision>
      <origin
        xyz="0 0 0"
        rpy="0 0 0" />
      <geometry>
        <mesh
          filename="https://raw.githubusercontent.com/shine-tong/urdf/main/sa2000h_urdf_0416/meshes/link2.STL" />
      </geometry>
    </collision>
  </link>
  <joint
    name="joint2"
    type="revolute">
    <origin
      xyz="0.19 0 0"
      rpy="1.5708 -1.5708 0" />
    <parent
      link="link1" />
    <child
      link="link2" />
    <axis
      xyz="0 0 -1" />
    <limit
      lower="-1.3963"
      upper="2.8449"
      effort="0"
      velocity="0" />
  </joint>
  <link
    name="link3">
    <inertial>
      <origin
        xyz="0.10114 -0.11148 0.022868"
        rpy="0 0 0" />
      <mass
        value="0.11857" />
      <inertia
        ixx="0.0020813"
        ixy="0.00098222"
        ixz="-8.4727E-05"
        iyy="0.0020002"
        iyz="0.00018768"
        izz="0.00255" />
    </inertial>
    <visual>
      <origin
        xyz="0 0 0"
        rpy="0 0 0" />
      <geometry>
        <mesh
          filename="https://raw.githubusercontent.com/shine-tong/urdf/main/sa2000h_urdf_0416/meshes/link3.STL" />
      </geometry>
      <material
        name="">
        <color
          rgba="1 1 0.50196 1" />
      </material>
    </visual>
    <collision>
      <origin
        xyz="0 0 0"
        rpy="0 0 0" />
      <geometry>
        <mesh
          filename="https://raw.githubusercontent.com/shine-tong/urdf/main/sa2000h_urdf_0416/meshes/link3.STL" />
      </geometry>
    </collision>
  </link>
  <joint
    name="joint3"
    type="revolute">
    <origin
      xyz="0.765 0 0"
      rpy="0 0 0" />
    <parent
      link="link2" />
    <child
      link="link3" />
    <axis
      xyz="0 0 -1" />
    <limit
      lower="-1.3963"
      upper="1.3963"
      effort="0"
      velocity="0" />
  </joint>
  <link
    name="link4">
    <inertial>
      <origin
        xyz="-0.017718 0.037821 -0.38898"
        rpy="0 0 0" />
      <mass
        value="0.087667" />
      <inertia
        ixx="0.0040784"
        ixy="3.1743E-05"
        ixz="0.00013383"
        iyy="0.0039608"
        iyz="-0.00065713"
        izz="0.00042402" />
    </inertial>
    <visual>
      <origin
        xyz="0 0 0"
        rpy="0 0 0" />
      <geometry>
        <mesh
          filename="https://raw.githubusercontent.com/shine-tong/urdf/main/sa2000h_urdf_0416/meshes/link4.STL" />
      </geometry>
      <material
        name="">
        <color
          rgba="1 1 0.50196 1" />
      </material>
    </visual>
    <collision>
      <origin
        xyz="0 0 0"
        rpy="0 0 0" />
      <geometry>
        <mesh
          filename="https://raw.githubusercontent.com/shine-tong/urdf/main/sa2000h_urdf_0416/meshes/link4.STL" />
      </geometry>
    </collision>
  </link>
  <joint
    name="joint4"
    type="revolute">
    <origin
      xyz="0.2 -1.0365 0"
      rpy="1.5708 0 0" />
    <parent
      link="link3" />
    <child
      link="link4" />
    <axis
      xyz="0 0 -1" />
    <limit
      lower="-1.6"
      upper="1.6"
      effort="0"
      velocity="0" />
  </joint>
  <link
    name="link5">
    <inertial>
      <origin
        xyz="-0.030544 1.7764E-05 -0.0095094"
        rpy="0 0 0" />
      <mass
        value="0.0080739" />
      <inertia
        ixx="1.7885E-05"
        ixy="-4.3741E-09"
        ixz="2.5238E-06"
        iyy="1.848E-05"
        iyz="5.3798E-09"
        izz="1.7098E-05" />
    </inertial>
    <visual>
      <origin
        xyz="0 0 0"
        rpy="0 0 0" />
      <geometry>
        <mesh
          filename="https://raw.githubusercontent.com/shine-tong/urdf/main/sa2000h_urdf_0416/meshes/link5.STL" />
      </geometry>
      <material
        name="">
        <color
          rgba="1 1 0.50196 1" />
      </material>
    </visual>
    <collision>
      <origin
        xyz="0 0 0"
        rpy="0 0 0" />
      <geometry>
        <mesh
          filename="https://raw.githubusercontent.com/shine-tong/urdf/main/sa2000h_urdf_0416/meshes/link5.STL" />
      </geometry>
    </collision>
  </link>
  <joint
    name="joint5"
    type="revolute">
    <origin
      xyz="0 0 0"
      rpy="1.5708 1.5708 0" />
    <parent
      link="link4" />
    <child
      link="link5" />
    <axis
      xyz="0 0 1" />
    <limit
      lower="-2.2689"
      upper="2.2689"
      effort="0"
      velocity="0" />
  </joint>
  <link
    name="link6">
    <inertial>
      <origin
        xyz="0.0035718 2.4745E-05 0.18029"
        rpy="0 0 0" />
      <mass
        value="0.57011" />
      <inertia
        ixx="0.0004224"
        ixy="5.1093E-07"
        ixz="-1.3921E-05"
        iyy="0.0004059"
        iyz="1.3539E-08"
        izz="0.00059093" />
    </inertial>
    <visual>
      <origin
        xyz="0 0 0"
        rpy="0 0 0" />
      <geometry>
        <mesh
          filename="https://raw.githubusercontent.com/shine-tong/urdf/main/sa2000h_urdf_0416/meshes/link6.STL" />
      </geometry>
      <material
        name="">
        <color
          rgba="0.79216 0.81961 0.93333 1" />
      </material>
    </visual>
    <collision>
      <origin
        xyz="0 0 0"
        rpy="0 0 0" />
      <geometry>
        <mesh
          filename="https://raw.githubusercontent.com/shine-tong/urdf/main/sa2000h_urdf_0416/meshes/link6.STL" />
      </geometry>
    </collision>
  </link>
  <joint
    name="joint6"
    type="revolute">
    <origin
      xyz="0 0 0"
      rpy="1.5708 0 -1.5708" />
    <parent
      link="link5" />
    <child
      link="link6" />
    <axis
      xyz="0 0 -1" />
    <limit
      lower="-6.2832"
      upper="6.2832"
      effort="0"
      velocity="0" />
  </joint>

  <link name="link_flp">
    <collision>
      <geometry>
        <box size="0.0001 0.0001 0.0001"/>
      </geometry>
      <origin rpy="0 0 0" xyz="0 0 0"/>
    </collision>
  </link>

  <joint name="joint_flp" type="fixed">
    <parent link="link6"/>
    <child link="link_flp"/>
    <!-- 法兰盘 0.0995-->
    <origin rpy="0 0 3.1415926" xyz="0 0 0.10"/>
  </joint>

  <link name="link_tool">
  </link>

  <joint name="joint_tool" type="fixed">
    <parent link="link_flp"/>
    <child link="link_tool"/>
    <origin xyz="-0.0834289 -0.000416569 0.436365" rpy="0.000145299 0.55089 3.13687"/>  
  </joint>

</robot>
